<?xml version="1.0"?>
<robot name="mini_cheetah">
  <!-- Cuerpo principal -->
  <link name="base">
    <inertial>
      <origin xyz="0 0 0"/>
      <mass value="2.0"/>
      <inertia ixx="0.02" ixy="0" ixz="0" iyy="0.05" iyz="0" izz="0.06"/>
    </inertial>
    <visual>
      <geometry>
        <box size="0.3 0.1 0.05"/>
      </geometry>
      <material name="blue">
        <color rgba="0 0 1 1"/>
      </material>
    </visual>
    <collision>
      <geometry>
        <box size="0.3 0.1 0.05"/>
      </geometry>
    </collision>
  </link>
  <!-- Pata delantera izquierda -->
  <link name="fl_hip">
    <inertial>
      <origin xyz="0 0 0"/>
      <mass value="0.1"/>
      <inertia ixx="0.0001" ixy="0" ixz="0" iyy="0.0001" iyz="0" izz="0.0001"/>
    </inertial>
    <visual>
      <geometry>
        <cylinder length="0.06" radius="0.01"/>
      </geometry>
      <material name="black">
        <color rgba="0 0 0 1"/>
      </material>
    </visual>
    <collision>
      <geometry>
        <cylinder length="0.06" radius="0.01"/>
      </geometry>
    </collision>
  </link>
  <joint name="fl_hip_joint" type="revolute">
    <parent link="base"/>
    <child link="fl_hip"/>
    <origin xyz="0.15 0.05 0" rpy="0 0 0"/>
    <axis xyz="0 1 0"/>
    <limit lower="-1.57" upper="1.57" effort="2" velocity="2"/>
  </joint>
  <link name="fl_knee">
    <inertial>
      <origin xyz="0 0 0"/>
      <mass value="0.05"/>
      <inertia ixx="0.00005" ixy="0" ixz="0" iyy="0.00005" iyz="0" izz="0.00005"/>
    </inertial>
    <visual>
      <geometry>
        <cylinder length="0.10" radius="0.008"/>
      </geometry>
      <material name="gray">
        <color rgba="0.5 0.5 0.5 1"/>
      </material>
    </visual>
    <collision>
      <geometry>
        <cylinder length="0.10" radius="0.008"/>
      </geometry>
    </collision>
  </link>
  <joint name="fl_knee_joint" type="revolute">
    <parent link="fl_hip"/>
    <child link="fl_knee"/>
    <origin xyz="0 0 -0.03" rpy="0 0 0"/>
    <axis xyz="0 1 0"/>
    <limit lower="-2.0" upper="0.0" effort="2" velocity="2"/>
  </joint>
  <!-- Pata delantera derecha -->
  <link name="fr_hip">
    <inertial>
      <origin xyz="0 0 0"/>
      <mass value="0.1"/>
      <inertia ixx="0.0001" ixy="0" ixz="0" iyy="0.0001" iyz="0" izz="0.0001"/>
    </inertial>
    <visual>
      <geometry>
        <cylinder length="0.06" radius="0.01"/>
      </geometry>
      <material name="black"/>
    </visual>
    <collision>
      <geometry>
        <cylinder length="0.06" radius="0.01"/>
      </geometry>
    </collision>
  </link>
  <joint name="fr_hip_joint" type="revolute">
    <parent link="base"/>
    <child link="fr_hip"/>
    <origin xyz="0.15 -0.05 0" rpy="0 0 0"/>
    <axis xyz="0 1 0"/>
    <limit lower="-1.57" upper="1.57" effort="2" velocity="2"/>
  </joint>
  <link name="fr_knee">
    <inertial>
      <origin xyz="0 0 0"/>
      <mass value="0.05"/>
      <inertia ixx="0.00005" ixy="0" ixz="0" iyy="0.00005" iyz="0" izz="0.00005"/>
    </inertial>
    <visual>
      <geometry>
        <cylinder length="0.10" radius="0.008"/>
      </geometry>
      <material name="gray"/>
    </visual>
    <collision>
      <geometry>
        <cylinder length="0.10" radius="0.008"/>
      </geometry>
    </collision>
  </link>
  <joint name="fr_knee_joint" type="revolute">
    <parent link="fr_hip"/>
    <child link="fr_knee"/>
    <origin xyz="0 0 -0.03" rpy="0 0 0"/>
    <axis xyz="0 1 0"/>
    <limit lower="-2.0" upper="0.0" effort="2" velocity="2"/>
  </joint>
  <!-- Pata trasera izquierda -->
  <link name="rl_hip">
    <inertial>
      <origin xyz="0 0 0"/>
      <mass value="0.1"/>
      <inertia ixx="0.0001" ixy="0" ixz="0" iyy="0.0001" iyz="0" izz="0.0001"/>
    </inertial>
    <visual>
      <geometry>
        <cylinder length="0.06" radius="0.01"/>
      </geometry>
      <material name="black"/>
    </visual>
    <collision>
      <geometry>
        <cylinder length="0.06" radius="0.01"/>
      </geometry>
    </collision>
  </link>
  <joint name="rl_hip_joint" type="revolute">
    <parent link="base"/>
    <child link="rl_hip"/>
    <origin xyz="-0.15 0.05 0" rpy="0 0 0"/>
    <axis xyz="0 1 0"/>
    <limit lower="-1.57" upper="1.57" effort="2" velocity="2"/>
  </joint>
  <link name="rl_knee">
    <inertial>
      <origin xyz="0 0 0"/>
      <mass value="0.05"/>
      <inertia ixx="0.00005" ixy="0" ixz="0" iyy="0.00005" iyz="0" izz="0.00005"/>
    </inertial>
    <visual>
      <geometry>
        <cylinder length="0.10" radius="0.008"/>
      </geometry>
      <material name="gray"/>
    </visual>
    <collision>
      <geometry>
        <cylinder length="0.10" radius="0.008"/>
      </geometry>
    </collision>
  </link>
  <joint name="rl_knee_joint" type="revolute">
    <parent link="rl_hip"/>
    <child link="rl_knee"/>
    <origin xyz="0 0 -0.03" rpy="0 0 0"/>
    <axis xyz="0 1 0"/>
    <limit lower="-2.0" upper="0.0" effort="2" velocity="2"/>
  </joint>
  <!-- Pata trasera derecha -->
  <link name="rr_hip">
    <inertial>
      <origin xyz="0 0 0"/>
      <mass value="0.1"/>
      <inertia ixx="0.0001" ixy="0" ixz="0" iyy="0.0001" iyz="0" izz="0.0001"/>
    </inertial>
    <visual>
      <geometry>
        <cylinder length="0.06" radius="0.01"/>
      </geometry>
      <material name="black"/>
    </visual>
    <collision>
      <geometry>
        <cylinder length="0.06" radius="0.01"/>
      </geometry>
    </collision>
  </link>
  <joint name="rr_hip_joint" type="revolute">
    <parent link="base"/>
    <child link="rr_hip"/>
    <origin xyz="-0.15 -0.05 0" rpy="0 0 0"/>
    <axis xyz="0 1 0"/>
    <limit lower="-1.57" upper="1.57" effort="2" velocity="2"/>
  </joint>
  <link name="rr_knee">
    <inertial>
      <origin xyz="0 0 0"/>
      <mass value="0.05"/>
      <inertia ixx="0.00005" ixy="0" ixz="0" iyy="0.00005" iyz="0" izz="0.00005"/>
    </inertial>
    <visual>
      <geometry>
        <cylinder length="0.10" radius="0.008"/>
      </geometry>
      <material name="gray"/>
    </visual>
    <collision>
      <geometry>
        <cylinder length="0.10" radius="0.008"/>
      </geometry>
    </collision>
  </link>
  <joint name="rr_knee_joint" type="revolute">
    <parent link="rr_hip"/>
    <child link="rr_knee"/>
    <origin xyz="0 0 -0.03" rpy="0 0 0"/>
    <axis xyz="0 1 0"/>
    <limit lower="-2.0" upper="0.0" effort="2" velocity="2"/>
  </joint>
</robot>
